{
  "comments": [
    {
      "unresolved": false,
      "key": {
        "uuid": "c7c0c319_0bb3bb00",
        "filename": "/PATCHSET_LEVEL",
        "patchSetId": 5
      },
      "lineNbr": 0,
      "author": {
        "id": 1000022
      },
      "writtenOn": "2022-01-10T14:50:05Z",
      "side": 1,
      "message": "\u003e Patch Set 3:\n\u003e \n\u003e \u003e \u003e \u003e stderr:\n\u003e \u003e \u003e \u003e terminate called after throwing an instance of \u0027sdbusplus::exception::SdBusError\u0027\n\u003e \u003e \u003e \u003e   what():  sd_bus_request_name: org.freedesktop.DBus.Error.FileExists: File exists\n\u003e \u003e \u003e \u003e ------------------------------------------------------------------------------\n\u003e \u003e \u003e Where are the `sd_bus_request_name` calls even coming from during the tests?\n\u003e \u003e \n\u003e \u003e I don\u0027t see that the sd_bus_request_name is being called during the tests, Patrick If I remove all the test and keep only one test then it is getting timedout.\n\u003e \n\u003e I\u0027m lost.  We\u0027re throwing an error that can only be created from this sdbusplus code:\n\u003e \n\u003e     /** @brief Claim a service name on the dbus.\n\u003e      *\n\u003e      *  @param[in] service - The service name to claim.\n\u003e      */\n\u003e     void request_name(const char* service)\n\u003e     {\n\u003e         int r \u003d _intf-\u003esd_bus_request_name(_bus.get(), service, 0);\n\u003e         if (r \u003c 0)\n\u003e         {\n\u003e             throw exception::SdBusError(-r, \"sd_bus_request_name\");\n\u003e         }\n\u003e     }\n\nIt has been solved, now the CI has been passed.",
      "revId": "206c44f34d5f3963ac0ef08ccf9fccf6c8a887e4",
      "serverId": "adbd0a64-1f21-4d83-b585-671fe73cb6e4"
    }
  ]
}